<?xml version="1.0"?>
<robot xmlns:xacro="http://www.ros.org/wiki/xacro">

    <xacro:macro name="roller_macro" params="parent name xyz rpy">

        <link name="roller_${name}_rim_${parent}_link">

            <inertial>
                <mass value="0.125"/>
                <inertia ixx="2.78642013e-06" ixy="0" ixz="0" iyy="2.78642013e-6" iyz="0" izz="1.62134920e-06"/>
            </inertial>
        
            <visual>
                <geometry>
                    <mesh filename="package://uv_robot_description/meshes/roller.stl" scale="1 1 1"/>
                </geometry>
                <material name="roller_material">
                    <color rgba="0.1 0.1 0.1 1"/>
                </material>
            </visual>

            <collision>
                <geometry>
                    <mesh filename="package://uv_robot_description/meshes/roller.stl" scale="1 1 1"/>
                </geometry>
            </collision>

        </link>

        <joint name="roller_${name}_rim_${parent}_link" type="continuous">
            <parent link="rim_${parent}_link"/>
            <child link="roller_${name}_rim_${parent}_link"/>
            <axis xyz="0 0 1"/>
            <origin xyz="${xyz}" rpy="${rpy}"/>
        </joint>

        <gazebo reference="roller_${name}_rim_${parent}_link">
            <material>Gazebo/Black</material>
        </gazebo>

    </xacro:macro>
</robot>