<?xml version="1.0"?>

<robot xmlns:xacro="http://www.ros.org/wiki/xacro">

    <xacro:macro name="tube_macro" params="name xyz rpy">

        <link name="${name}_servo_link">
            <pose>0 0 0 0 0</pose>

            <inertial>
                <mass value="2"/>
                <origin rpy="0 0 0" xyz="0 0 0"/>
                <inertia ixx="0.0395416666667" ixy="0" ixz="0" iyy="0.10620833333" iyz="0" izz="0.106208333333"/>
            </inertial>

            <visual>
                <geometry>
                    <mesh filename="package://uv_robot_description/meshes/servo_mech.stl"/>
                </geometry>
            </visual>

            <collision>
                <geometry>
                    <mesh filename="package://uv_robot_description/meshes/servo_mech.stl"/>
                </geometry>
            </collision>
        </link>

        <link name="${name}_base_link">
            <inertial>
                <mass value="0.5"/>
                <origin rpy="0 0 0" xyz="0 0 0.1"/>
                <inertia ixx="0.0395416666667" ixy="0" ixz="0" iyy="0.10620833333" iyz="0" izz="0.106208333333"/>
            </inertial>

            <visual>
                <geometry>
                    <mesh filename="package://uv_robot_description/meshes/tube_mech_Base.stl"/>
                </geometry>
            </visual>

            <collision>
                <geometry>
                    <mesh filename="package://uv_robot_description/meshes/tube_mech_Base.stl"/>
                </geometry>
            </collision>
        </link>

        <link name="${name}_tube_link">
            <inertial>
                <mass value="0.4"/>
                <origin rpy="0 0 0" xyz="0 0 0.1"/>
                <inertia ixx="0.0395416666667" ixy="0" ixz="0" iyy="0.10620833333" iyz="0" izz="0.106208333333"/>
            </inertial>

            <visual>
                <geometry>
                    <mesh filename="package://uv_robot_description/meshes/tube_mech_Tubes.stl"/>
                </geometry>
            </visual>

            <collision>
                <geometry>
                    <mesh filename="package://uv_robot_description/meshes/tube_mech_Tubes.stl"/>
                </geometry>
            </collision>
        </link>

        <joint name="${name}_base_tube_joint" type="revolute">
            <origin xyz="0 -0.06 0.065" rpy="0 0 0"/>
            <parent link="${name}_base_link"/>
            <child link="${name}_tube_link"/>
            <axis xyz="1 0 0"/>
            <limit lower="0" upper="1.5708" effort="10" velocity="3"/>
        </joint>

        <joint name="${name}_servo_base_joint" type="prismatic">
            <origin xyz="0 0 0.045" rpy="0 0 3.14159"/>
            <parent link="${name}_servo_link"/>
            <child link="${name}_base_link"/>
            <axis xyz="0 0 1"/>
            <limit lower="0" upper="0.85" effort="10" velocity="3"/>
        </joint>

        <joint name="main_base_${name}_tube_joint" type="fixed">
            <origin xyz="${xyz}" rpy="${rpy}"/>
            <parent link="base_link"/>
            <child link="${name}_servo_link"/>
        </joint>

        <transmission name="${name}_base_transmission">
            <type>transmission_interface/SimpleTransmission</type>
            <actuator name="${name}_base_motor">
                <mechanicalReduction>1</mechanicalReduction>
            </actuator>
            <joint name="${name}_servo_base_joint">
                <hardwareInterface>hardware_interface/PositionJointInterface</hardwareInterface>
            </joint>
        </transmission>

        <transmission name="${name}_tube_transmission">
            <type>transmission_interface/SimpleTransmission</type>
            <actuator name="${name}_tube_motor">
                <mechanicalReduction>1</mechanicalReduction>
            </actuator>
            <joint name="${name}_base_tube_joint">
                <hardwareInterface>hardware_interface/PositionJointInterface</hardwareInterface>
            </joint>
        </transmission>

    </xacro:macro>
</robot>

                
